## <a name="react_error_handling"></a>Обработка ошибок в React компоненте

Предпочтительный способ обработать ошибку в React компоненте - поймать исключение через Rx в rejected хендлере и показать вместо ожидаемой компоненты что-то вписывающееся по-месту по-смыслу:
```tsx
<Rx
  value$={value$}
  children={(value) => <SomeComponent />}
  pending={() => <SomeComponent.Pending />}
  rejected={(error, reload) => <SomeComponent.Rejected reload={reload} />}
/>
```

Это самый простой и базовый способ обработать ошибку.
При этом такая ошибка не будет отправлена в sentry и не будет перехвачена в React error boundary, т.к. мы её перехватываем внутри observable.

В rejected callback вторым аргументом приходит опциональный параметр `reload`.
Важно понимать, что reload будет передан в callback только если value$ является Observable c Wrapped данными и при создании rejected wrapped был передан reload callback:

```ts
const reloadIntent$ = new BehaviourSubject<void>(undefined)
const observable$: Observable<Wrapped<UserData>> = reloadIntent$.pipe(
    switchMap(() => getUserById(id)),
    startWith(pendingWrapped),
	map(data => createFulfilledWrapped(data)),
	catchError(error => {
	    return of(createRejectedWrapped(error, () => reloadIntent$.next())) // второй аргумент - reload, который будет передан в rejected callback
	}),
)
```
Приведённый выше пример лишь один из вариантов применения reload. В реальном приложении в reload можно указать например метод перезапроса graphql query.

Чтобы ошибка прокидывалась из компонента нужно не передать `rejected` и установить флаг `raiseUnhandledErrors`:

```ts
<Rx
  value$={value$}
  children={(value) => <SomeComponent />}
  pending={() => <SomeComponent.Pending />}
  raiseUnhandledErrors
/>
```

Либо можно сделать re-throw:
```ts
<Rx
  value$={value$}
  children={(value) => <SomeComponent />}
  pending={() => <SomeComponent.Pending />}
  rejected={error => {
    throw error
  }}
/>
```

## Обработка ошибок в логике
Зачастую нужно сделать какие-то дополнительные действия над ошибкой, например показать toast с ошибкой пользователю. Это лучше всего делать через `tap` где-нибудь в контроллере или сервисе (там, где описывается логика получения данных):
```ts
const observable$ = getUserById(id).pipe(
  unwrap(),
  tap({
	  error: (error) => {
	    snackbarService.show(error)
	  },
  })
)
```

Либо если это wrapped данные:
```ts
const observable$ = getUserById(id).pipe(
  tap(data => {
    if (data.status === 'rejected') {
        snackbarService.show(data.error)
    }
  })
)
```

## Перехват ошибки оператором catchError()

Если данные из observable поступают в сыром виде, т.е. не `wrapped`, то ошибки можно обработать стандартным для RxJS способом:

```ts
const observable$ = getUserById(id).pipe(
  retry(3),
  catchError(() => {
	  return of(undefined)
  }),
)
```

Более сложный пример:
```ts
const observable$ = getUserById(id).pipe(
	catchError(error => {
		if (isErrorExpected(error)) {
			return throwError(() => new ExpectedError())
		}
		return throwError(() => error)
	}),
	retryWhen(errors => errors.pipe(
		filter(error => error instanceof ExpectedError), // повторять только если ожидаемая ошибка
		take(3), // повторять только 3 раза
		delay(1000) // ждать секунду перед каждым повторением
	)),
)
```

https://www.learnrxjs.io/learn-rxjs/operators/error_handling/retrywhen

Если же это wrapped, то ошибка уже отловлена и лучшим решением будет просто довести до Rx компонента данные и действовать по пути [Обработка ошибок в React компоненте](#react_error_handling)
